python3: can't open file '/home/unknown/ai-time-traveler/rust_code/ai-ground-up/validation_results/20250915_095830_COMPLETE/validation_results/20250915_095830_COMPLETE/final_analysis.py': [Errno 2] No such file or directory
